Workbook

Sheet 1-Project Setup
A1: ENTERPRISE STEEL ESTIMATING SYSTEM
A3: PROJECT INFORMATION
A4: Project Name: | D4: Project #:
A5: Client/Owner: | D5: Date:
A6: Location: | D6: Estimator:
A7: Architect: | D7: Phone:
A8: Engineer: | D8: Email:
A9: General Contractor:
J10: Building Type | K10: Structure Type
A11: PROJECT SPECIFICATIONS | J11: Commercial | K11: Moment Frame
A12: Building Type: | C12: Total Weight: | E12: TONS | J12: Industrial | K12: Braced Frame
A13: Structure Type: | C13: Square Footage: | E13: SF | J13: Institutional | K13: Simple Span
A14: Height: | C14: Stories: | E14: EA | J14: Bridge | K14: Other
A15: Seismic Design Cat: | C15: Wind Speed: | E15: MPH | J15: Other
A16: Exposure Category: | C16: Risk Category:
A18: COMPANY LABOR RATES
A19: Position | B19: Base Rate | C19: Burden % | D19: Total Rate | E19: Notes
A20: Project Manager | B20: $55.00 | C20: 45% | D20: =B20*(1+C20) | E20: Supervision
A21: Superintendent | B21: $52.00 | C21: 45% | D21: =B21*(1+C21) | E21: Field Oversight
A22: Foreman | B22: $48.00 | C22: 45% | D22: =B22*(1+C22) | E22: Crew Lead
A23: Welder (Certified) | B23: $45.00 | C23: 45% | D23: =B23*(1+C23) | E23: CWI/AWS D1.1
A24: Rigger (Certified) | B24: $42.00 | C24: 45% | D24: =B24*(1+C24) | E24: NCCCO/NCCER
A25: Ironworker Journeyman | B25: $38.00 | C25: 45% | D25: =B25*(1+C25) | E25: General
A26: Ironworker Apprentice | B26: $28.00 | C26: 45% | D26: =B26*(1+C26) | E26: Training
A27: Crane Operator | B27: $50.00 | C27: 45% | D27: =B27*(1+C27) | E27: NCCCO
A29: BURDEN BREAKDOWN
A30: Workers Comp: | B30: 18.5% | C30: FICA: | D30: 7.65%
A31: FUTA/SUTA: | B31: 3.5% | C31: Benefits: | D31: 15%
A32: Total Burden: | B32: =SUM(B30+B31+D30+D31)
A34: MARKUP STRUCTURE
A35: Overhead: | B35: 15% | C35: Profit: | D35: 12%
A36: Contingency: | B36: 5% | C36: Bond: | D36: 1%
A37: Sales Tax:

Sheet 2-Fabrication
A1: Line | B1: Category | C1: Item Description | D1: Spec/Material | E1: Unit | F1: Qty | G1: Weight | H1: Material $/Unit | I1: Material Cost | J1: Fab Hours | K1: Labor Rate | L1: Labor Cost | M1: Subtotal | N1: Markup % | O1: Total
A2: F-001 | B2: STRUCTURAL BEAMS | C2: W36x300 Beams | D2: A992 Gr50 | E2: LF | G2: 300 | H2: 4.25 | I2: =F2*H2 | J2: 0.35 | K2: 45 | L2: =J2*K2 | M2: =I2+L2 | N2: 15% | O2: =M2*(1+N2)
A3: F-002 | C3: W36x230 Beams | D3: A992 Gr50 | E3: LF | G3: 230 | H3: 3.85 | I3: =F3*H3 | J3: 0.30 | K3: 45 | L3: =J3*K3 | M3: =I3+L3 | N3: 15% | O3: =M3*(1+N3)
A4: F-003 | C4: W33x241 Beams | D4: A992 Gr50 | E4: LF | G4: 241 | H4: 3.65 | I4: =F4*H4 | J4: 0.28 | K4: 45 | L4: =J4*K4 | M4: =I4+L4 | N4: 15% | O4: =M4*(1+N4)
A5: F-004 | C5: W30x211 Beams | D5: A992 Gr50 | E5: LF | G5: 211 | H5: 3.45 | I5: =F5*H5 | J5: 0.26 | K5: 45 | L5: =J5*K5 | M5: =I5+L5 | N5: 15% | O5: =M5*(1+N5)
A6: F-005 | C6: W27x194 Beams | D6: A992 Gr50 | E6: LF | G6: 194 | H6: 3.25 | I6: =F6*H6 | J6: 0.24 | K6: 45 | L6: =J6*K6 | M6: =I6+L6 | N6: 15% | O6: =M6*(1+N6)
A7: F-006 | C7: W24x162 Beams | D7: A992 Gr50 | E7: LF | G7: 162 | H7: 3.05 | I7: =F7*H7 | J7: 0.22 | K7: 45 | L7: =J7*K7 | M7: =I7+L7 | N7: 15% | O7: =M7*(1+N7)
A8: F-007 | C8: W21x147 Beams | D8: A992 Gr50 | E8: LF | G8: 147 | H8: 2.85 | I8: =F8*H8 | J8: 0.20 | K8: 45 | L8: =J8*K8 | M8: =I8+L8 | N8: 15% | O8: =M8*(1+N8)
A9: F-008 | C9: W18x119 Beams | D9: A992 Gr50 | E9: LF | G9: 119 | H9: 2.65 | I9: =F9*H9 | J9: 0.18 | K9: 45 | L9: =J9*K9 | M9: =I9+L9 | N9: 15% | O9: =M9*(1+N9)
A10: F-009 | C10: W16x100 Beams | D10: A992 Gr50 | E10: LF | G10: 100 | H10: 2.45 | I10: =F10*H10 | J10: 0.16 | K10: 45 | L10: =J10*K10 | M10: =I10+L10 | N10: 15% | O10: =M10*(1+N10)
A11: F-010 | C11: W14x90 Beams | D11: A992 Gr50 | E11: LF | G11: 90 | H11: 2.25 | I11: =F11*H11 | J11: 0.15 | K11: 45 | L11: =J11*K11 | M11: =I11+L11 | N11: 15% | O11: =M11*(1+N11)
A12: F-011 | C12: W14x74 Beams | D12: A992 Gr50 | E12: LF | G12: 74 | H12: 2.05 | I12: =F12*H12 | J12: 0.14 | K12: 45 | L12: =J12*K12 | M12: =I12+L12 | N12: 15% | O12: =M12*(1+N12)
A13: F-012 | C13: W12x65 Beams | D13: A992 Gr50 | E13: LF | G13: 65 | H13: 1.85 | I13: =F13*H13 | J13: 0.13 | K13: 45 | L13: =J13*K13 | M13: =I13+L13 | N13: 15% | O13: =M13*(1+N13)
A14: F-013 | C14: W12x53 Beams | D14: A992 Gr50 | E14: LF | G14: 53 | H14: 1.65 | I14: =F14*H14 | J14: 0.12 | K14: 45 | L14: =J14*K14 | M14: =I14+L14 | N14: 15% | O14: =M14*(1+N14)
... A21: F-020 | C21: W6x25 Beams | D21: A992 Gr50 | E21: LF | G21: 25 | H21: 0.85 | I21: =F21*H21 | J21: 0.06 | K21: 45 | L21: =J21*K21 | M21: =I21+L21 | N21: 15% | O21: =M21*(1+N21)
A22: F-021 | B22: HSS COLUMNS | C22: HSS 12x12x5/8 | D22: A500 GrC | E22: LF | G22: 76.1 | H22: 5.25 | I22: =F22*H22 | J22: 0.45 | K22: 45 | L22: =J22*K22 | M22: =I22+L22 | N22: 15% | O22: =M22*(1+N22)
A23: F-022 | C23: HSS 12x12x1/2 | D23: A500 GrC | E23: LF | G23: 62.5 | H23: 4.85 | I23: =F23*H23 | J23: 0.40 | K23: 45 | L23: =J23*K23 | M23: =I23+L23 | N23: 15% | O23: =M23*(1+N23)
A24: F-023 | C24: HSS 10x10x1/2 | D24: A500 GrC | E24: LF | G24: 51.0 | H24: 4.25 | I24: =F24*H24 | J24: 0.35 | K24: 45 | L24: =J24*K24 | M24: =I24+L24 | N24: 15% | O24: =M24*(1+N24)
A25: F-024 | C25: HSS 10x10x3/8 | D25: A500 GrC | E25: LF | G25: 39.4 | H25: 3.85 | I25: =F25*H25 | J25: 0.32 | K25: 45 | L25: =J25*K25 | M25: =I25+L25 | N25: 15% | O25: =M25*(1+N25)
A26: F-025 | C26: HSS 8x8x1/2 | D26: A500 GrC | E26: LF | G26: 40.4 | H26: 3.65 | I26: =F26*H26 | J26: 0.30 | K26: 45 | L26: =J26*K26 | M26: =I26+L26 | N26: 15% | O26: =M26*(1+N26)
A27: F-026 | C27: HSS 8x8x3/8 | D27: A500 GrC | E27: LF | G27: 31.0 | H27: 3.25 | I27: =F27*H27 | J27: 0.28 | K27: 45 | L27: =J27*K27 | M27: =I27+L27 | N27: 15% | O27: =M27*(1+N27)
A28: F-027 | C28: HSS 6x6x3/8 | D28: A500 GrC | E28: LF | G28: 22.4 | H28: 2.85 | I28: =F28*H28 | J28: 0.25 | K28: 45 | L28: =J28*K28 | M28: =I28+L28 | N28: 15% | O28: =M28*(1+N28)
A29: F-028 | C29: HSS 6x6x1/4 | D29: A500 GrC | E29: LF | G29: 15.6 | H29: 2.45 | I29: =F29*H29 | J29: 0.22 | K29: 45 | L29: =J29*K29 | M29: =I29+L29 | N29: 15% | O29: =M29*(1+N29)
A30: F-029 | C30: HSS 4x4x1/4 | D30: A500 GrC | E30: LF | G30: 10.0 | H30: 2.05 | I30: =F30*H30 | J30: 0.20 | K30: 45 | L30: =J30*K30 | M30: =I30+L30 | N30: 15% | O30: =M30*(1+N30)
A31: F-030 | B31: CONNECTION PLATES | C31: PL 1x18x18 | D31: A36 | E31: EA | G31: 115 | H31: 0.65 | I31: =F31*H31 | J31: 1.20 | K31: 45 | L31: =J31*K31 | M31: =I31+L31 | N31: 15% | O31: =M31*(1+N31)
A32: F-031 | C32: PL 3/4x16x16 | D32: A36 | E32: EA | G32: 65 | H32: 0.65 | I32: =F32*H32 | J32: 1.00 | K32: 45 | L32: =J32*K32 | M32: =I32+L32 | N32: 15% | O32: =M32*(1+N32)
A33: F-032 | C33: PL 5/8x14x14 | D33: A36 | E33: EA | G33: 47 | H33: 0.65 | I33: =F33*H33 | J33: 0.85 | K33: 45 | L33: =J33*K33 | M33: =I33+L33 | N33: 15% | O33: =M33*(1+N33)
A34: F-033 | C34: PL 1/2x12x12 | D34: A36 | E34: EA | G34: 31 | H34: 0.65 | I34: =F34*H34 | J34: 0.70 | K34: 45 | L34: =J34*K34 | M34: =I34+L34 | N34: 15% | O34: =M34*(1+N34)
A35: F-034 | C35: PL 3/8x10x10 | D35: A36 | E35: EA | G35: 19 | H35: 0.65 | I35: =F35*H35 | J35: 0.55 | K35: 45 | L35: =J35*K35 | M35: =I35+L35 | N35: 15% | O35: =M35*(1+N35)
A36: F-035 | C36: Gusset Plates (various) | D36: A36 | E36: LB | G36: 1 | H36: 0.65 | I36: =F36*H36 | J36: 0.015 | K36: 45 | L36: =J36*K36 | M36: =I36+L36 | N36: 15% | O36: =M36*(1+N36)
A37: F-036 | B37: MISCELLANEOUS | C37: L4x4x1/4 Angles | D37: A36 | E37: LF | G37: 6.6 | H37: 1.15 | I37: =F37*H37 | J37: 0.08 | K37: 45 | L37: =J37*K37 | M37: =I37+L37 | N37: 15% | O37: =M37*(1+N37)
A38: F-037 | C38: L3x3x1/4 Angles | D38: A36 | E38: LF | G38: 4.9 | H38: 0.95 | I38: =F38*H38 | J38: 0.07 | K38: 45 | L38: =J38*K38 | M38: =I38+L38 | N38: 15% | O38: =M38*(1+N38)
A39: F-038 | C39: C12x30 Channels | D39: A36 | E39: LF | G39: 30 | H39: 1.85 | I39: =F39*H39 | J39: 0.15 | K39: 45 | L39: =J39*K39 | M39: =I39+L39 | N39: 15% | O39: =M39*(1+N39)
A40: F-039 | C40: C10x20 Channels | D40: A36 | E40: LF | G40: 20 | H40: 1.45 | I40: =F40*H40 | J40: 0.12 | K40: 45 | L40: =J40*K40 | M40: =I40+L40 | N40: 15% | O40: =M40*(1+N40)
A41: F-040 | C41: Flat Bar (various) | D41: A36 | E41: LB | G41: 1 | H41: 0.65 | I41: =F41*H41 | J41: 0.012 | K41: 45 | L41: =J41*K41 | M41: =I41+L41 | N41: 15% | O41: =M41*(1+N41)
A42: F-041 | B42: STEEL DECK | C42: B Roof Deck 22ga | D42: G60 Galv | E42: SF | G42: 1.9 | H42: 0.95 | I42: =F42*H42 | J42: 0.015 | K42: 45 | L42: =J42*K42 | M42: =I42+L42 | N42: 15% | O42: =M42*(1+N42)
A43: F-042 | C43: B Roof Deck 20ga | D43: G60 Galv | E43: SF | G43: 2.1 | H43: 1.05 | I43: =F43*H43 | J43: 0.018 | K43: 45 | L43: =J43*K43 | M43: =I43+L43 | N43: 15% | O43: =M43*(1+N43)
A44: F-043 | C44: B Roof Deck 18ga | D44: G60 Galv | E44: SF | G44: 2.5 | H44: 1.25 | I44: =F44*H44 | J44: 0.022 | K44: 45 | L44: =J44*K44 | M44: =I44+L44 | N44: 15% | O44: =M44*(1+N44)
A45: F-044 | C45: N Floor Deck 22ga | D45: G60 Galv | E45: SF | G45: 2.0 | H45: 1.15 | I45: =F45*H45 | J45: 0.020 | K45: 45 | L45: =J45*K45 | M45: =I45+L45 | N45: 15% | O45: =M45*(1+N45)
A46: F-045 | C46: N Floor Deck 20ga | D46: G60 Galv | E46: SF | G46: 2.3 | H46: 1.35 | I46: =F46*H46 | J46: 0.025 | K46: 45 | L46: =J46*K46 | M46: =I46+L46 | N46: 15% | O46: =M46*(1+N46)
...

Sheet 3-Erection
A1: Line | B1: Category | C1: Description | D1: Unit | E1: Qty | F1: Crew | G1: Hrs/Unit | H1: Total Hrs | I1: Rate | J1: Labor Cost | K1: Equipment | L1: Subtotal | M1: Markup | N1: Total
A2: E-001 | B2: MOBILIZATION | C2: Site Mobilization | D2: LS | E2: 1 | F2: 4 | G2: 8 | H2: =E2*G2 | I2: 45 | J2: =H2*I2 | K2: 1850 | L2: =J2+K2 | M2: 12% | N2: =L2*(1+M2)
A3: E-002 | C3: Site Survey/Layout | D3: DAY | F3: 2 | G3: 6 | H3: =E3*G3 | I3: 45 | J3: =H3*I3 | K3: 450 | L3: =J3+K3 | M3: 12% | N3: =L3*(1+M3)
A4: E-003 | C4: Safety Setup/Perimeter | D4: LS | E4: 1 | F4: 2 | G4: 12 | H4: =E4*G4 | I4: 45 | J4: =H4*I4 | K4: 650 | L4: =J4+K4 | M4: 12% | N4: =L4*(1+M4)
A5: E-004 | B5: CRANE | C5: Crane 60-ton + Operator | D5: DAY | F5: 1 | G5: 8 | H5: =E5*G5 | I5: 65 | J5: =H5*I5 | K5: 1850 | L5: =J5+K5 | M5: 12% | N5: =L5*(1+M5)
A6: E-005 | C6: Crane 80-ton + Operator | D6: DAY | F6: 1 | G6: 8 | H6: =E6*G6 | I6: 65 | J6: =H6*I6 | K6: 2450 | L6: =J6+K6 | M6: 12% | N6: =L6*(1+M6)
A7: E-006 | C7: Crane 100-ton + Operator | D7: DAY | F7: 1 | G7: 8 | H7: =E7*G7 | I7: 65 | J7: =H7*I7 | K7: 3200 | L7: =J7+K7 | M7: 12% | N7: =L7*(1+M7)
A8: E-007 | C8: Rigging Equipment | D8: DAY | F8: 0 | G8: 0 | H8: =E8*8 | I8: 0 | J8: =H8*I8 | K8: 450 | L8: =J8+K8 | M8: 12% | N8: =L8*(1+M8)
A9: E-008 | B9: HANDLING | C9: Unload/Distribute Steel | D9: TON | F9: 3 | G9: 0.4 | H9: =E9*G9 | I9: 45 | J9: =H9*I9 | K9: 35 | L9: =J9+K9 | M9: 12% | N9: =L9*(1+M9)
A10: E-009 | B10: COLUMNS | C10: HSS Column (heavy) | D10: EA | F10: 5 | G10: 3.5 | H10: =E10*G10 | I10: 45 | J10: =H10*I10 | K10: 225 | L10: =J10+K10 | M10: 12% | N10: =L10*(1+M10)
A11: E-010 | C11: HSS Column (medium) | D11: EA | F11: 4 | G11: 2.5 | H11: =E11*G11 | I11: 45 | J11: =H11*I11 | K11: 175 | L11: =J11+K11 | M11: 12% | N11: =L11*(1+M11)
A12: E-011 | C12: HSS Column (light) | D12: EA | F12: 3 | G12: 1.5 | H12: =E12*G12 | I12: 45 | J12: =H12*I12 | K12: 125 | L12: =J12+K12 | M12: 12% | N12: =L12*(1+M12)
A13: E-012 | B13: BEAMS | C13: W36-W40 Beam | D13: EA | F13: 5 | G13: 2.5 | H13: =E13*G13 | I13: 45 | J13: =H13*I13 | K13: 195 | L13: =J13+K13 | M13: 12% | N13: =L13*(1+M13)
A14: E-013 | C14: W30-W33 Beam | D14: EA | F14: 4 | G14: 2.0 | H14: =E14*G14 | I14: 45 | J14: =H14*I14 | K14: 155 | L14: =J14+K14 | M14: 12% | N14: =L14*(1+M14)
A15: E-014 | C15: W24-W27 Beam | D15: EA | F15: 4 | G15: 1.6 | H15: =E15*G15 | I15: 45 | J15: =H15*I15 | K15: 125 | L15: =J15+K15 | M15: 12% | N15: =L15*(1+M15)
A16: E-015 | C16: W18-W21 Beam | D16: EA | F16: 3 | G16: 1.2 | H16: =E16*G16 | I16: 45 | J16: =H16*I16 | K16: 95 | L16: =J16+K16 | M16: 12% | N16: =L16*(1+M16)
A17: E-016 | C17: W14-W16 Beam | D17: EA | F17: 3 | G17: 0.9 | H17: =E17*G17 | I17: 45 | J17: =H17*I17 | K17: 75 | L17: =J17+K17 | M17: 12% | N17: =L17*(1+M17)
A18: E-017 | C18: W10-W12 Beam | D18: EA | F18: 3 | G18: 0.7 | H18: =E18*G18 | I18: 45 | J18: =H18*I18 | K18: 60 | L18: =J18+K18 | M18: 12% | N18: =L18*(1+M18)
A19: E-018 | C19: W8-W10 Beam | D19: EA | F19: 2 | G19: 0.5 | H19: =E19*G19 | I19: 45 | J19: =H19*I19 | K19: 45 | L19: =J19+K19 | M19: 12% | N19: =L19*(1+M19)
A20: E-019 | B20: CONNECTIONS | C20: Bolted (simple) | D20: EA | F20: 2 | G20: 0.25 | H20: =E20*G20 | I20: 45 | J20: =H20*I20 | K20: 15 | L20: =J20+K20 | M20: 12% | N20: =L20*(1+M20)
A21: E-020 | C21: Bolted (complex) | D21: EA | F21: 2 | G21: 0.5 | H21: =E21*G21 | I21: 45 | J21: =H21*I21 | K21: 25 | L21: =J21+K21 | M21: 12% | N21: =L21*(1+M21)
A22: E-021 | C22: Field Weld (fillet) | D22: LF | F22: 2 | G22: 0.15 | H22: =E22*G22 | I22: 55 | J22: =H22*I22 | K22: 20 | L22: =J22+K22 | M22: 12% | N22: =L22*(1+M22)
A23: E-022 | C23: Field Weld (groove) | D23: LF | F23: 2 | G23: 0.35 | H23: =E23*G23 | I23: 55 | J23: =H23*I23 | K23: 35 | L23: =J23+K23 | M23: 12% | N23: =L23*(1+M23)
A24: E-023 | B24: DECKING | C24: Roof Deck | D24: SF | F24: 2 | G24: 0.012 | H24: =E24*G24 | I24: 45 | J24: =H24*I24 | K24: 8 | L24: =J24+K24 | M24: 12% | N24: =L24*(1+M24)
A25: E-024 | C25: Floor Deck | D25: SF | F25: 2 | G25: 0.015 | H25: =E25*G25 | I25: 45 | J25: =H25*I25 | K25: 10 | L25: =J25+K25 | M25: 12% | N25: =L25*(1+M25)
A26: E-025 | C26: Shear Stud Welding | D26: EA | F26: 2 | G26: 0.08 | H26: =E26*G26 | I26: 55 | J26: =H26*I26 | K26: 15 | L26: =J26+K26 | M26: 12% | N26: =L26*(1+M26)
A27: E-026 | B27: SAFETY | C27: Daily Safety Meeting | D27: DAY | F27: 4 | G27: 0.5 | H27: =E27*G27 | I27: 45 | J27: =H27*I27 | K27: 0 | L27: =J27+K27 | M27: 12% | N27: =L27*(1+M27)
A28: E-027 | C28: Fall Protection | D28: EA | F28: 2 | G28: 2 | H28: =E28*G28 | I28: 45 | J28: =H28*I28 | K28: 125 | L28: =J28+K28 | M28: 12% | N28: =L28*(1+M28)
A29: E-028 | C29: Debris Removal | D29: DAY | F29: 2 | G29: 2 | H29: =E29*G29 | I29: 45 | J29: =H29*I29 | K29: 185 | L29: =J29+K29 | M29: 12% | N29: =L29*(1+M29)
A30: E-029 | C30: Final Cleanup | D30: LS | E30: 1 | F30: 4 | G30: 8 | H30: =E30*G30 | I30: 45 | J30: =H30*I30 | K30: 650 | L30: =J30+K30 | M30: 12% | N30: =L30*(1+M30)
A31: E-030 | C31: Demobilization | D31: LS | E31: 1 | F31: 4 | G31: 6 | H31: =E31*G31 | I31: 45 | J31: =H31*I31 | K31: 950 | L31: =J31+K31 | M31: 12% | N31: =L31*(1+M31)
A33: ERECTION TOTAL | N33: =SUM(N2:N31)

Sheet 4-Summary
A1: ENTERPRISE PROJECT COST SUMMARY
A3: COST CATEGORY | B3: SUBTOTAL | C3: MARKUP | D3: TOTAL
A4: FABRICATION
A5: Structural Steel Materials | B5: ='2-Fabrication'!O78 | C5: 15% | D5: =B5*(1+C5)
A6: Freight/Shipping | B6: Included
A7: Subcontractors (Galv, etc.) | B7: Included
A8: Fabrication Subtotal | B8: =B5 | D8: =D5
A10: ERECTION
A11: Labor (All Crew) | B11: ='3-Erection'!N33 | C11: 12% | D11: =B11*(1+C11)
A12: Equipment (Cranes, etc.) | B12: =SUM('3-Erection'!K2:K31) | C12: 12% | D12: =B12*(1+C12)
A13: Erection Subtotal | B13: =B11+B12 | D13: =D11+D12
A15: PROJECT SUBTOTAL | B15: =B8+B13 | D15: =D8+D13
A17: OVERHEAD & PROFIT
A18: Overhead (15%) | B18: =B15*0.15
A19: Profit (12%) | B19: =B15*0.12
A20: Contingency (5%) | B20: =B15*0.05
A21: Bond (1%) | B21: =B15*0.01
A22: Total O&P | B22: =SUM(B18:B21)
A24: TOTAL PROJECT COST | B24: =B15+B22
A26: METRICS
A27: Total Weight (tons): | B27: ='1-Project Setup'!D12
A28: Price per Ton: | B28: =IF(B27>0,B24/B27,0)
A29: Square Footage: | B29: ='1-Project Setup'!D13
A30: Price per SF: | B30: =IF(B29>0,B24/B29,0)
A32: BID INFORMATION
A33: Bid Validity: | B33: 30 days
A34: Payment Terms: | B34: Net 15
A35: Retainage: | B35: 10%
A37: APPROVAL
A38: Estimator: | C38: Date:
A39: Manager: | C39: Date:
